import { render, screen } from '@/utils/test-utils'
import { ErrorBoundary } from './ErrorBoundary'

// Component that throws an error for testing
function ThrowError({ shouldThrow = false }: { shouldThrow?: boolean }) {
  if (shouldThrow) {
    throw new Error('Test error')
  }
  return <div>No error</div>
}

describe('ErrorBoundary', () => {
  beforeEach(() => {
    // Suppress console.error for these tests
    vi.spyOn(console, 'error').mockImplementation(() => {})
  })

  afterEach(() => {
    vi.restoreAllMocks()
  })

  it('renders children when there is no error', () => {
    render(
      <ErrorBoundary>
        <ThrowError shouldThrow={false} />
      </ErrorBoundary>
    )

    expect(screen.getByText('No error')).toBeInTheDocument()
  })

  it('renders error UI when child component throws', () => {
    render(
      <ErrorBoundary>
        <ThrowError shouldThrow={true} />
      </ErrorBoundary>
    )

    expect(screen.getByText('Something went wrong')).toBeInTheDocument()
    expect(screen.getByText(/We're sorry, but something unexpected happened/)).toBeInTheDocument()
    expect(screen.getByRole('button', { name: 'Refresh Page' })).toBeInTheDocument()
  })

  it('renders custom fallback when provided', () => {
    const customFallback = <div>Custom error message</div>

    render(
      <ErrorBoundary fallback={customFallback}>
        <ThrowError shouldThrow={true} />
      </ErrorBoundary>
    )

    expect(screen.getByText('Custom error message')).toBeInTheDocument()
    expect(screen.queryByText('Something went wrong')).not.toBeInTheDocument()
  })

  it('calls onError callback when error occurs', () => {
    const onError = vi.fn()

    render(
      <ErrorBoundary onError={onError}>
        <ThrowError shouldThrow={true} />
      </ErrorBoundary>
    )

    expect(onError).toHaveBeenCalledWith(
      expect.any(Error),
      expect.objectContaining({
        componentStack: expect.any(String)
      })
    )
  })
})